# 错误处理机制

- [错误处理机制](#错误处理机制)
  - [1.Error实例对象](#1error实例对象)
  - [2.原生错误类型](#2原生错误类型)
    - [2.1 SyntaxError对象](#21-syntaxerror对象)
    - [2.2 ReferenceError对象](#22-referenceerror对象)
    - [2.3 RangeError对象](#23-rangeerror对象)
    - [2.4 TypeError对象](#24-typeerror对象)
    - [2.5 URIError对象](#25-urierror对象)
    - [2.6 EvalError对象](#26-evalerror对象)
    - [2.7 总结](#27-总结)
  - [3.自定义错误](#3自定义错误)
  - [4.throw语句](#4throw语句)
  - [5.try...catch结构](#5trycatch结构)
  - [6. finally代码块](#6-finally代码块)

## 1.Error实例对象

JavaScript解析或运行时，一旦发生错误，引擎就会抛出一个错误对象。JavaScript原生提供$\color{#ea4335}{Error}$构造函数，所有抛出的错误都是这个构造函数的实例

```js
var err = new Error('出错了');
err.message // "出错了"
```

抛出Error实例对象以后，整个程序就中断在发生错误的地方，不再往下执行。

$\color{#ea4335}{Error}$实例对象必须有$\color{#ea4335}{message}$属性，表示出错时的提示信息，$\color{#ea4335}{Error}$实例对象还提供$\color{#ea4335}{name}$和$\color{#ea4335}{stack}$属性，但它们是非标准的

- message：错误提示信息
- name：错误名称（非标准属性
- stack：错误的堆栈（非标准属性

例子：

```js
function throwit() {
    throw new Error('我是一个错误对象');
}

function catchit() {
    try {
        throwit();
    } catch (e) {
        console.log(e.stack); // print stack trace
    }
}

catchit()
/**
 * Error: 我是一个错误对象
    at throwit (index.js:2)
    at catchit (index.js:7)
    at index.js:13
 */
```

## 2.原生错误类型

$\color{#ea4335}{Error}$实例对象是最一般的错误类型，在它的基础上，JavaScript还定义了其他6种错误对象

### 2.1 SyntaxError对象

$\color{#ea4335}{SyntaxError对象}$是解析代码发生的语法错误，可能为

- 变量名错误
- 缺少括号等

```js
// 变量名错误
var 1a;
// Uncaught SyntaxError: Invalid or unexpected token

// 缺少括号
console.log 'hello');
// Uncaught SyntaxError: Unexpected string
```

### 2.2 ReferenceError对象

$\color{#ea4335}{ReferenceError}$对象发生在

- 是用一个不存在变量时发生的错误
- 将一个值分配给无法分配的对象

```js
// 使用一个不存在的变量
unknownVariable
// Uncaught ReferenceError: unknownVariable is not defined

// 等号左侧不是变量
console.log() = 1
// Uncaught ReferenceError: Invalid left-hand side in assignment
```

### 2.3 RangeError对象

$\color{#ea4335}{RangeError}$对象是一个超出有效范围时发生的错误，主要有下面几种情况

- 数据长度为负数
- $\color{#ea4335}{Number}$对象的方法超出范围
- 函数堆栈超过最大值

```js
// 数组长度不得为负数
new Array(-1)
// Uncaught RangeError: Invalid array length
```

### 2.4 TypeError对象

$\color{#ea4335}{TypeError}$对象是变量或参数不是预期类型时发生的错误，比如

- 对字符串，布尔值、数值这种原始类型使用$\color{#ea4335}{new}$命令
- 调用对象不存在的方法

```js
new 123
// Uncaught TypeError: 123 is not a constructor

var obj = {};
obj.unknownMethod()
// Uncaught TypeError: obj.unknownMethod is not a function
```

### 2.5 URIError对象

$\color{#ea4335}{URIError}$对象是URI相关函数不正确时抛出的错误，主要涉及

$\color{#ea4335}{encodeURI()、decodeURI()、encodeURIComponent()、decodeURIComponent()、escape()和unescape()}$

这六个函数

```js
decodeURI('%2')
// URIError: URI malformed
```

### 2.6 EvalError对象

$\color{#ea4335}{eval}$函数没有被正确执行时，会抛出$\color{#ea4335}{EvalError}$错误。该错误类型已经不再使用了，只是为了保证与以前代码兼容才继续保留

### 2.7 总结

以上这6种派生错误，连同原始的Error对象，都是构造函数。开发者可以使用它们，手动生成错误对象的实例。这些构造函数都接受一个参数，代表错误提示信息（message）。

```js
var err1 = new Error('出错了！');
var err2 = new RangeError('出错了，变量超出有效范围！');
var err3 = new TypeError('出错了，变量类型无效！');

err1.message // "出错了！"
err2.message // "出错了，变量超出有效范围！"
err3.message // "出错了，变量类型无效！"
```

## 3.自定义错误

除了JavaScript原生提供的七种错误对象，还可以定义自己的错误对象

```js
function UserError(message) {
  this.message = message || '默认信息';
  this.name = 'UserError';
}

UserError.prototype = new Error();
UserError.prototype.constructor = UserError;

new UserError('这是自定义的错误！');
```

## 4.throw语句

$\color{#ea4335}{throw}$语句的作用是手动中断程序执行，抛出一个错误

$\color{#ea4335}{throw}$可以抛出任何类型的值,也就是说,它的参数可以是任何值

```js
// 抛出一个字符串
throw 'Error！';
// Uncaught Error

// 抛出一个数值
throw 42;
// Uncaught 42

// 抛出一个布尔值
throw true;
// Uncaught true

// 抛出一个对象
throw {
  toString: function () {
    return 'Error!';
  }
};
// Uncaught {toString: ƒ}
```

## 5.try...catch结构

一旦发生错误，程序就中止执行了。JavaScript 提供了try...catch结构，允许对错误进行处理，选择是否往下执行。

为了捕捉不同类型的错误，catch代码块之中可以加入判断语句。

```js
try {
  foo.bar();
} catch (e) {
  if (e instanceof EvalError) {
    console.log(e.name + ": " + e.message);
  } else if (e instanceof RangeError) {
    console.log(e.name + ": " + e.message);
  }
  // ...
}
```

## 6. finally代码块

定义:

$\color{#ea4335}{try...catch}$结构允许在最后添加一个$\color{#ea4335}{finally}$代码块，不管是否出现错误，都必须在最后运行的语句。

$\color{#ea4335}{return}$语句的执行是排在$\color{#ea4335}{finally}$代码之前，只是等$\color{#ea4335}{finally}$代码执行完毕后才返回

```js
var count = 0;
function countUp() {
  try {
    return count;
  } finally {
    count++;
  }
}

countUp()
// 0
count
// 1
```

在$\color{#ea4335}{catch}$代码块中,触发转入$\color{#ea4335}{finally}$代码块的标志,有:

- $\color{#ea4335}{return}$语句
- $\color{#ea4335}{throw}$语句

```js
function f() {
  try {
    console.log(0);
    throw 'bug';
  } catch(e) {
    console.log(1);
    return true; // 这句原本会延迟到 finally 代码块结束再执行
    console.log(2); // 不会运行
  } finally {
    console.log(3);
    return false; // 这句会覆盖掉前面那句 return
    console.log(4); // 不会运行
  }

  console.log(5); // 不会运行
}

var result = f();
// 0
// 1
// 3

result
// false
```

```js
function f() {
  try {
    throw '出错了！';
  } catch(e) {
    console.log('捕捉到内部错误');
    throw e; // 这句原本会等到finally结束再执行
  } finally {
    return false; // 直接返回
  }
}

try {
  f();
} catch(e) {
  // 此处不会执行
  console.log('caught outer "bogus"');
}

//  捕捉到内部错误
```

上述代码中,进入$\color{#ea4335}{catch}$代码块之后,一遇到$\color{#ea4335}{throw}$语句,就会去执行$\color{#ea4335}{finally}$代码块,其中有$\color{#ea4335}{return false}$语句,因此就直接返回了,不会再回去执行$\color{#ea4335}{catch}$代码块剩下的部分了
